Workbook

Sheet Dashboard
A1: MAM-ON ELEMENTARY SCHOOL School-Based Performance Management Dashboard | AA1: Helper Metric | AB1: Value | AD1: Subject | AE1: MPS | AG1: Grade | AH1: AtRisk
AA2: Total Learners | AB2: =COUNTA(Students!B2:B500) -> 130 | AD2: English | AE2: =AVERAGEIF(Scores!D:D,AD2,Scores!H:H) -> 0.47408333 | AG2: Kinder | AH2: =SUMIF(Scores!B:B,AG2,Scores!J:J) -> 4
AA3: Teachers | AB3: =COUNTA(Teacher_Submissions!B2:B100) -> 6 | AD3: Filipino | AE3: =AVERAGEIF(Scores!D:D,AD3,Scores!H:H) -> 0.5973 | AG3: Grade 1 | AH3: =SUMIF(Scores!B:B,AG3,Scores!J:J) -> 26
A4: School Year: | B4: 2026-2027 | D4: Quarter: | E4: 1st Quarter | G4: Data Source: | H4: LIS Export + Excel + Power Automate | L4: Last Refresh: | M4: 2026-07-27 10:40 AM | AA4: Submitted | AB4: =COUNTIF(Teacher_Submissions!K2:K100,"Submitted") -> 2 | AD4: Mathematics | AE4: =AVERAGEIF(Scores!D:D,AD4,Scores!H:H) -> 0.43425 | AG4: Grade 2 | AH4: =SUMIF(Scores!B:B,AG4,Scores!J:J) -> 28
AA5: Due Soon | AB5: =COUNTIF(Teacher_Submissions!K2:K100,"Due Soon") -> 2 | AD5: Science | AE5: =AVERAGEIF(Scores!D:D,AD5,Scores!H:H) -> 0.48 | AG5: Grade 3 | AH5: =SUMIF(Scores!B:B,AG5,Scores!J:J) -> 12
A6: 👥 | B6: TOTAL LEARNERS | D6: 👩‍🏫 | E6: TEACHERS | G6: 📊 | H6: OVERALL MPS | J6: ⚠️ | K6: AT-RISK LEARNERS | M6: ✅ | N6: SUBMISSION RATE | AA6: Overdue | AB6: =COUNTIF(Teacher_Submissions!K2:K100,"Overdue") -> 0 | AD6: GMRC | AE6: =AVERAGEIF(Scores!D:D,AD6,Scores!H:H) -> 0.55 | AG6: Grade 4 | AH6: =SUMIF(Scores!B:B,AG6,Scores!J:J) -> 18
AA7: For Checking | AB7: =COUNTIF(Teacher_Submissions!K2:K100,"For Checking") -> 1 | AD7: Readiness | AE7: =AVERAGEIF(Scores!D:D,AD7,Scores!H:H) -> 0.583 | AG7: Grade 5 | AH7: =SUMIF(Scores!B:B,AG7,Scores!J:J) -> 26
B8: =AB2 -> 130 | E8: =AB3 -> 6 | H8: =AB11 -> 0.502475 | K8: =AB10 -> 137 | N8: =AB9 -> 0.33333333 | AA8: Returned | AB8: =COUNTIF(Teacher_Submissions!K2:K100,"Returned") -> 1 | AG8: Grade 6 | AH8: =SUMIF(Scores!B:B,AG8,Scores!J:J) -> 23
B9: 100% Local Database | E9: 6 Advisers / Users | H9: School Average | K9: For Intervention | N9: Teacher Compliance | AA9: Submission Rate | AB9: =IFERROR(AB4/AB3,0) -> 0.33333333
AA10: At-Risk Learners | AB10: =SUM(Scores!J2:J200) -> 137
A11: TEACHER SUBMISSION STATUS PER TEACHER | H11: MPS BY GRADE LEVEL | AA11: Overall MPS | AB11: =AVERAGE(Scores!H2:H200) -> 0.502475
A12: Teacher | B12: Grade | C12: Status | D12: Date Submitted | E12: Deadline | F12: Remarks | H12: Kinder | I12: Grade 1 | J12: Grade 2 | K12: Grade 3 | L12: Grade 4 | M12: Grade 5 | N12: Grade 6
A13: =Teacher_Submissions!B2 -> Jenny Queen L. Orillaneda | B13: =Teacher_Submissions!C2 -> Grade 1 | C13: =Teacher_Submissions!K2 -> Submitted | D13: =Teacher_Submissions!I2 -> 2026-07-27 | E13: =Teacher_Submissions!H2 -> 2026-07-30 | F13: =Teacher_Submissions!M2 -> Complete | H13: =AVERAGEIF(Scores!B:B,"Kinder",Scores!H:H) -> 0.583 | I13: =AVERAGEIF(Scores!B:B,"Grade 1",Scores!H:H) -> 0.5 | J13: =AVERAGEIF(Scores!B:B,"Grade 2",Scores!H:H) -> 0.42666667 | K13: =AVERAGEIF(Scores!B:B,"Grade 3",Scores!H:H) -> 0.63 | L13: =AVERAGEIF(Scores!B:B,"Grade 4",Scores!H:H) -> 0.47666667 | M13: =AVERAGEIF(Scores!B:B,"Grade 5",Scores!H:H) -> 0.48883333 | N13: =AVERAGEIF(Scores!B:B,"Grade 6",Scores!H:H) -> 0.46666667 | AA13: Target Feeding Days | AB13: 20
A14: =Teacher_Submissions!B3 -> Maria Fatima R. Peñanueva | B14: =Teacher_Submissions!C3 -> Grade 2 | C14: =Teacher_Submissions!K3 -> Due Soon | D14: =Teacher_Submissions!I3 -> 0 | E14: =Teacher_Submissions!H3 -> 2026-07-30 | F14: =Teacher_Submissions!M3 -> 0
A15: =Teacher_Submissions!B4 -> Jessa Mae R. Flores | B15: =Teacher_Submissions!C4 -> Grade 3 | C15: =Teacher_Submissions!K4 -> Submitted | D15: =Teacher_Submissions!I4 -> 2026-07-27 | E15: =Teacher_Submissions!H4 -> 2026-07-30 | F15: =Teacher_Submissions!M4 -> Complete
A16: =Teacher_Submissions!B5 -> Alma C. Nayre | B16: =Teacher_Submissions!C5 -> Grade 4 | C16: =Teacher_Submissions!K5 -> For Checking | D16: =Teacher_Submissions!I5 -> 2026-07-26 | E16: =Teacher_Submissions!H5 -> 2026-07-30 | F16: =Teacher_Submissions!M5 -> Needs checking
A17: =Teacher_Submissions!B6 -> Lendon B. Abonales | B17: =Teacher_Submissions!C6 -> Grade 5 | C17: =Teacher_Submissions!K6 -> Due Soon | D17: =Teacher_Submissions!I6 -> 0 | E17: =Teacher_Submissions!H6 -> 2026-07-20 | F17: =Teacher_Submissions!M6 -> 0
A18: =Teacher_Submissions!B7 -> Mark Zoilo C. Tajonera | B18: =Teacher_Submissions!C7 -> Grade 6 | C18: =Teacher_Submissions!K7 -> Returned | D18: =Teacher_Submissions!I7 -> 2026-07-25 | E18: =Teacher_Submissions!H7 -> 2026-07-30 | F18: =Teacher_Submissions!M7 -> Needs correction
A20: Submitted | B20: Due Soon | C20: Overdue | D20: For Checking | E20: Returned | F20: Overall Rate
A21: =AB4 -> 2 | B21: =AB5 -> 2 | C21: =AB6 -> 0 | D21: =AB7 -> 1 | E21: =AB8 -> 1 | F21: =AB9 -> 0.33333333
A24: SUBJECT PERFORMANCE | H24: AT-RISK LEARNERS BY GRADE
A38: TOP COMPETENCIES NEEDING IMPROVEMENT
A39: Priority Need | B39: Subject | C39: Grade | D39: At-Risk Learners
A40: Fractions and decimals | B40: Mathematics | C40: Grade 5 | D40: 12
A41: Multi-step word math | B41: Mathematics | C41: Grade 2 | D41: 11
A42: Ratio and percentage | B42: Mathematics | C42: Grade 6 | D42: 10
A43: Reading fluency | B43: English | C43: Grade 2 | D43: 10
A44: Letter-sound recognition | B44: English | C44: Grade 1 | D44: 8
F46: QUICK ACTIONS 1. Upload latest LIS export to SharePoint/OneDrive folder. 2. Power Automate updates Students and LIS_Sync_Log sheets. 3. Teachers encode scores in Scores sheet or via Power Apps. 4. Submission status updates automatically from DateSubmitted and ReviewStatus. 5. Principal opens Dashboard for live monitoring.
A54: RECENT ASSESSMENT SUBMISSIONS FROM TEACHER LINK
A55: Date | B55: Teacher | C55: Grade | D55: Assessment | E55: Subject | F55: MPS | G55: Status | H55: File
A56: =Assessment_Submissions!B5 -> 46230.389 | B56: =Assessment_Submissions!C5 -> Jenny Queen L. Orillaneda | C56: =Assessment_Submissions!D5 -> Grade 1 | D56: =Assessment_Submissions!G5 -> Periodical Exam | E56: =Assessment_Submissions!H5 -> English | F56: =Assessment_Submissions!L5 -> 0.72 | G56: =Assessment_Submissions!S5 -> For Checking | H56: =IF(Assessment_Submissions!R5="","No File",HYPERLINK(Assessment_Submissions!R5,"View File")) -> View File
A57: =Assessment_Submissions!B6 -> 46230.424 | B57: =Assessment_Submissions!C6 -> Maria Fatima R. Peñanueva | C57: =Assessment_Submissions!D6 -> Grade 2 | D57: =Assessment_Submissions!G6 -> Summative Test | E57: =Assessment_Submissions!H6 -> Mathematics | F57: =Assessment_Submissions!L6 -> 0.525 | G57: =Assessment_Submissions!S6 -> For Checking | H57: =IF(Assessment_Submissions!R6="","No File",HYPERLINK(Assessment_Submissions!R6,"View File")) -> View File
A58: =Assessment_Submissions!B7 -> 46230.479 | B58: =Assessment_Submissions!C7 -> Jessa Mae R. Flores | C58: =Assessment_Submissions!D7 -> Grade 3 | D58: =Assessment_Submissions!G7 -> Diagnostic Test | E58: =Assessment_Submissions!H7 -> Filipino | F58: =Assessment_Submissions!L7 -> 0.8 | G58: =Assessment_Submissions!S7 -> Submitted | H58: =IF(Assessment_Submissions!R7="","No File",HYPERLINK(Assessment_Submissions!R7,"View File")) -> View File
A66: NEW MODULES ADDED: Teacher View-Only Dashboard, Learner Scores extraction table, Access Control, View-Only Sharing Guide, and Teacher Template Guide. Teachers should upload Excel files through Microsoft Forms and view updates through the protected Teacher_View_Dashboard or Power BI.
A70: Official class sections updated from provided class list: Kinder-KAMAGONG, Grade 1-MAGKONO, Grade 2-NARRA, Grade 3-TOOG, Grade 4-TUGAS, Grade 5-LAUAAN, Grade 6-YAKAL.
A74: Student Data Module Added: Use Student_Masterlist for official LIS/enrollment records, Enrollment_Dashboard for class counts, and Student_Data_Instructions for update steps. Placeholder learner names should be replaced with official school data.
A78: Student names imported from available MPS/summative files for Grade 1 MAGKONO, Grade 2 NARRA, Grade 4 TUGAS, Grade 5 LAUAAN, and Grade 6 YAKAL. Kinder KAMAGONG and Grade 3 TOOG still require populated learner data. LRN and personal profile fields still require official SF1/LIS verification.

Sheet Enrollment_Dashboard
A1: STUDENT ENROLLMENT DASHBOARD Summary of student enrollment by official class section and enrollment status. | AA1: Metric | AB1: Value
AA2: Total Students | AB2: =COUNTA(Student_Masterlist!B6:B230) -> 145
AA3: Active Students | AB3: =COUNTIF(Student_Masterlist!N6:N230,"Active") -> 145
AA4: For Verification | AB4: =COUNTIF(Student_Masterlist!N6:N230,"For Verification") -> 0
A5: TOTAL STUDENTS | D5: ACTIVE | G5: FOR VERIFICATION | J5: TRANSFERRED OUT | M5: DATA ISSUES | AA5: Transferred Out | AB5: =COUNTIF(Student_Masterlist!N6:N230,"Transferred Out") -> 0
B6: =AB2 -> 145 | E6: =AB3 -> 145 | H6: =AB4 -> 0 | K6: =AB5 -> 0 | N6: =AB7 -> 190 | AA6: Dropped | AB6: =COUNTIF(Student_Masterlist!N6:N230,"Dropped") -> 0
AA7: Data Issues | AB7: =COUNTIF(Student_Masterlist!W6:W230,"<>OK") -> 190
A8: All encoded learners | D8: Currently enrolled | G8: Need LIS checking | J8: Status monitoring | M8: Missing fields
A11: ENROLLMENT BY CLASS SECTION
A12: GradeLevel | B12: Section | C12: Active | D12: For Verification | E12: Transferred Out | F12: Dropped | G12: Total | H12: Adviser
A13: Kinder | B13: KAMAGONG | C13: =COUNTIFS(Student_Masterlist!J:J,A13,Student_Masterlist!K:K,B13,Student_Masterlist!N:N,"Active") -> 15 | D13: =COUNTIFS(Student_Masterlist!J:J,A13,Student_Masterlist!K:K,B13,Student_Masterlist!N:N,"For Verification") -> 0 | E13: =COUNTIFS(Student_Masterlist!J:J,A13,Student_Masterlist!K:K,B13,Student_Masterlist!N:N,"Transferred Out") -> 0 | F13: =COUNTIFS(Student_Masterlist!J:J,A13,Student_Masterlist!K:K,B13,Student_Masterlist!N:N,"Dropped") -> 0 | G13: =COUNTIFS(Student_Masterlist!J:J,A13,Student_Masterlist!K:K,B13) -> 15 | H13: Kinder Adviser
A14: Grade 1 | B14: MAGKONO | C14: =COUNTIFS(Student_Masterlist!J:J,A14,Student_Masterlist!K:K,B14,Student_Masterlist!N:N,"Active") -> 20 | D14: =COUNTIFS(Student_Masterlist!J:J,A14,Student_Masterlist!K:K,B14,Student_Masterlist!N:N,"For Verification") -> 0 | E14: =COUNTIFS(Student_Masterlist!J:J,A14,Student_Masterlist!K:K,B14,Student_Masterlist!N:N,"Transferred Out") -> 0 | F14: =COUNTIFS(Student_Masterlist!J:J,A14,Student_Masterlist!K:K,B14,Student_Masterlist!N:N,"Dropped") -> 0 | G14: =COUNTIFS(Student_Masterlist!J:J,A14,Student_Masterlist!K:K,B14) -> 20 | H14: Jenny Queen L. Orillaneda
A15: Grade 2 | B15: NARRA | C15: =COUNTIFS(Student_Masterlist!J:J,A15,Student_Masterlist!K:K,B15,Student_Masterlist!N:N,"Active") -> 20 | D15: =COUNTIFS(Student_Masterlist!J:J,A15,Student_Masterlist!K:K,B15,Student_Masterlist!N:N,"For Verification") -> 0 | E15: =COUNTIFS(Student_Masterlist!J:J,A15,Student_Masterlist!K:K,B15,Student_Masterlist!N:N,"Transferred Out") -> 0 | F15: =COUNTIFS(Student_Masterlist!J:J,A15,Student_Masterlist!K:K,B15,Student_Masterlist!N:N,"Dropped") -> 0 | G15: =COUNTIFS(Student_Masterlist!J:J,A15,Student_Masterlist!K:K,B15) -> 20 | H15: Maria Fatima R. Peñanueva
A16: Grade 3 | B16: TOOG | C16: =COUNTIFS(Student_Masterlist!J:J,A16,Student_Masterlist!K:K,B16,Student_Masterlist!N:N,"Active") -> 20 | D16: =COUNTIFS(Student_Masterlist!J:J,A16,Student_Masterlist!K:K,B16,Student_Masterlist!N:N,"For Verification") -> 0 | E16: =COUNTIFS(Student_Masterlist!J:J,A16,Student_Masterlist!K:K,B16,Student_Masterlist!N:N,"Transferred Out") -> 0 | F16: =COUNTIFS(Student_Masterlist!J:J,A16,Student_Masterlist!K:K,B16,Student_Masterlist!N:N,"Dropped") -> 0 | G16: =COUNTIFS(Student_Masterlist!J:J,A16,Student_Masterlist!K:K,B16) -> 20 | H16: Jessa Mae R. Flores
A17: Grade 4 | B17: TUGAS | C17: =COUNTIFS(Student_Masterlist!J:J,A17,Student_Masterlist!K:K,B17,Student_Masterlist!N:N,"Active") -> 16 | D17: =COUNTIFS(Student_Masterlist!J:J,A17,Student_Masterlist!K:K,B17,Student_Masterlist!N:N,"For Verification") -> 0 | E17: =COUNTIFS(Student_Masterlist!J:J,A17,Student_Masterlist!K:K,B17,Student_Masterlist!N:N,"Transferred Out") -> 0 | F17: =COUNTIFS(Student_Masterlist!J:J,A17,Student_Masterlist!K:K,B17,Student_Masterlist!N:N,"Dropped") -> 0 | G17: =COUNTIFS(Student_Masterlist!J:J,A17,Student_Masterlist!K:K,B17) -> 16 | H17: Alma C. Nayre
A18: Grade 5 | B18: LAUAAN | C18: =COUNTIFS(Student_Masterlist!J:J,A18,Student_Masterlist!K:K,B18,Student_Masterlist!N:N,"Active") -> 21 | D18: =COUNTIFS(Student_Masterlist!J:J,A18,Student_Masterlist!K:K,B18,Student_Masterlist!N:N,"For Verification") -> 0 | E18: =COUNTIFS(Student_Masterlist!J:J,A18,Student_Masterlist!K:K,B18,Student_Masterlist!N:N,"Transferred Out") -> 0 | F18: =COUNTIFS(Student_Masterlist!J:J,A18,Student_Masterlist!K:K,B18,Student_Masterlist!N:N,"Dropped") -> 0 | G18: =COUNTIFS(Student_Masterlist!J:J,A18,Student_Masterlist!K:K,B18) -> 21 | H18: Lendon B. Abonales
A19: Grade 6 | B19: YAKAL | C19: =COUNTIFS(Student_Masterlist!J:J,A19,Student_Masterlist!K:K,B19,Student_Masterlist!N:N,"Active") -> 33 | D19: =COUNTIFS(Student_Masterlist!J:J,A19,Student_Masterlist!K:K,B19,Student_Masterlist!N:N,"For Verification") -> 0 | E19: =COUNTIFS(Student_Masterlist!J:J,A19,Student_Masterlist!K:K,B19,Student_Masterlist!N:N,"Transferred Out") -> 0 | F19: =COUNTIFS(Student_Masterlist!J:J,A19,Student_Masterlist!K:K,B19,Student_Masterlist!N:N,"Dropped") -> 0 | G19: =COUNTIFS(Student_Masterlist!J:J,A19,Student_Masterlist!K:K,B19) -> 33 | H19: Mark Zoilo C. Tajonera

Sheet Student_Masterlist
A1: STUDENT DATA / ENROLLMENT MASTERLIST Use this sheet for official learner data from LIS export or manual enrollment updates. Replace placeholder learner names with actual student data.
A5: StudentID | B5: LRN | C5: LastName | D5: FirstName | E5: MiddleName | F5: FullName | G5: Sex | H5: Birthdate | I5: Age | J5: GradeLevel | K5: Section | L5: Adviser | M5: SchoolYear | N5: EnrollmentStatus | O5: DateEnrolled | P5: GuardianName | Q5: GuardianContact | R5: Address | S5: LIS_Status | T5: LastUpdated | U5: Source | V5: Remarks | W5: DataCheck
A6: 1 | B6: LRN-000000000001 | C6: Learner001 | D6: Sample | F6: =TRIM(D6&" "&E6&" "&C6) -> Sample Learner001 | I6: =IF(H6="","",DATEDIF(H6,TODAY(),"Y")) | J6: Kinder | K6: KAMAGONG | L6: Kinder Adviser | M6: 2026-2027 | N6: Active | O6: 46230 | S6: For LIS Verification | T6: 46230 | U6: Placeholder / Replace with LIS Export | W6: =IF(B6="","Missing LRN",IF(OR(J6="",K6=""),"Missing Grade/Section","OK")) -> OK
A7: 2 | B7: LRN-000000000002 | C7: Learner002 | D7: Sample | F7: =TRIM(D7&" "&E7&" "&C7) -> Sample Learner002 | I7: =IF(H7="","",DATEDIF(H7,TODAY(),"Y")) | J7: Kinder | K7: KAMAGONG | L7: Kinder Adviser | M7: 2026-2027 | N7: Active | O7: 46230 | S7: For LIS Verification | T7: 46230 | U7: Placeholder / Replace with LIS Export | W7: =IF(B7="","Missing LRN",IF(OR(J7="",K7=""),"Missing Grade/Section","OK")) -> OK
A8: 3 | B8: LRN-000000000003 | C8: Learner003 | D8: Sample | F8: =TRIM(D8&" "&E8&" "&C8) -> Sample Learner003 | I8: =IF(H8="","",DATEDIF(H8,TODAY(),"Y")) | J8: Kinder | K8: KAMAGONG | L8: Kinder Adviser | M8: 2026-2027 | N8: Active | O8: 46230 | S8: For LIS Verification | T8: 46230 | U8: Placeholder / Replace with LIS Export | W8: =IF(B8="","Missing LRN",IF(OR(J8="",K8=""),"Missing Grade/Section","OK")) -> OK
A9: 4 | B9: LRN-000000000004 | C9: Learner004 | D9: Sample | F9: =TRIM(D9&" "&E9&" "&C9) -> Sample Learner004 | I9: =IF(H9="","",DATEDIF(H9,TODAY(),"Y")) | J9: Kinder | K9: KAMAGONG | L9: Kinder Adviser | M9: 2026-2027 | N9: Active | O9: 46230 | S9: For LIS Verification | T9: 46230 | U9: Placeholder / Replace with LIS Export | W9: =IF(B9="","Missing LRN",IF(OR(J9="",K9=""),"Missing Grade/Section","OK")) -> OK
A10: 5 | B10: LRN-000000000005 | C10: Learner005 | D10: Sample | F10: =TRIM(D10&" "&E10&" "&C10) -> Sample Learner005 | I10: =IF(H10="","",DATEDIF(H10,TODAY(),"Y")) | J10: Kinder | K10: KAMAGONG | L10: Kinder Adviser | M10: 2026-2027 | N10: Active | O10: 46230 | S10: For LIS Verification | T10: 46230 | U10: Placeholder / Replace with LIS Export | W10: =IF(B10="","Missing LRN",IF(OR(J10="",K10=""),"Missing Grade/Section","OK")) -> OK
A11: 6 | B11: LRN-000000000006 | C11: Learner006 | D11: Sample | F11: =TRIM(D11&" "&E11&" "&C11) -> Sample Learner006 | I11: =IF(H11="","",DATEDIF(H11,TODAY(),"Y")) | J11: Kinder | K11: KAMAGONG | L11: Kinder Adviser | M11: 2026-2027 | N11: Active | O11: 46230 | S11: For LIS Verification | T11: 46230 | U11: Placeholder / Replace with LIS Export | W11: =IF(B11="","Missing LRN",IF(OR(J11="",K11=""),"Missing Grade/Section","OK")) -> OK
A12: 7 | B12: LRN-000000000007 | C12: Learner007 | D12: Sample | F12: =TRIM(D12&" "&E12&" "&C12) -> Sample Learner007 | I12: =IF(H12="","",DATEDIF(H12,TODAY(),"Y")) | J12: Kinder | K12: KAMAGONG | L12: Kinder Adviser | M12: 2026-2027 | N12: Active | O12: 46230 | S12: For LIS Verification | T12: 46230 | U12: Placeholder / Replace with LIS Export | W12: =IF(B12="","Missing LRN",IF(OR(J12="",K12=""),"Missing Grade/Section","OK")) -> OK
A13: 8 | B13: LRN-000000000008 | C13: Learner008 | D13: Sample | F13: =TRIM(D13&" "&E13&" "&C13) -> Sample Learner008 | I13: =IF(H13="","",DATEDIF(H13,TODAY(),"Y")) | J13: Kinder | K13: KAMAGONG | L13: Kinder Adviser | M13: 2026-2027 | N13: Active | O13: 46230 | S13: For LIS Verification | T13: 46230 | U13: Placeholder / Replace with LIS Export | W13: =IF(B13="","Missing LRN",IF(OR(J13="",K13=""),"Missing Grade/Section","OK")) -> OK
A14: 9 | B14: LRN-000000000009 | C14: Learner009 | D14: Sample | F14: =TRIM(D14&" "&E14&" "&C14) -> Sample Learner009 | I14: =IF(H14="","",DATEDIF(H14,TODAY(),"Y")) | J14: Kinder | K14: KAMAGONG | L14: Kinder Adviser | M14: 2026-2027 | N14: Active | O14: 46230 | S14: For LIS Verification | T14: 46230 | U14: Placeholder / Replace with LIS Export | W14: =IF(B14="","Missing LRN",IF(OR(J14="",K14=""),"Missing Grade/Section","OK")) -> OK
A15: 10 | B15: LRN-000000000010 | C15: Learner010 | D15: Sample | F15: =TRIM(D15&" "&E15&" "&C15) -> Sample Learner010 | I15: =IF(H15="","",DATEDIF(H15,TODAY(),"Y")) | J15: Kinder | K15: KAMAGONG | L15: Kinder Adviser | M15: 2026-2027 | N15: Active | O15: 46230 | S15: For LIS Verification | T15: 46230 | U15: Placeholder / Replace with LIS Export | W15: =IF(B15="","Missing LRN",IF(OR(J15="",K15=""),"Missing Grade/Section","OK")) -> OK
A16: 11 | B16: LRN-000000000011 | C16: Learner011 | D16: Sample | F16: =TRIM(D16&" "&E16&" "&C16) -> Sample Learner011 | I16: =IF(H16="","",DATEDIF(H16,TODAY(),"Y")) | J16: Kinder | K16: KAMAGONG | L16: Kinder Adviser | M16: 2026-2027 | N16: Active | O16: 46230 | S16: For LIS Verification | T16: 46230 | U16: Placeholder / Replace with LIS Export | W16: =IF(B16="","Missing LRN",IF(OR(J16="",K16=""),"Missing Grade/Section","OK")) -> OK
A17: 12 | B17: LRN-000000000012 | C17: Learner012 | D17: Sample | F17: =TRIM(D17&" "&E17&" "&C17) -> Sample Learner012 | I17: =IF(H17="","",DATEDIF(H17,TODAY(),"Y")) | J17: Kinder | K17: KAMAGONG | L17: Kinder Adviser | M17: 2026-2027 | N17: Active | O17: 46230 | S17: For LIS Verification | T17: 46230 | U17: Placeholder / Replace with LIS Export | W17: =IF(B17="","Missing LRN",IF(OR(J17="",K17=""),"Missing Grade/Section","OK")) -> OK
... A20: 15 | B20: LRN-000000000015 | C20: Learner015 | D20: Sample | F20: =TRIM(D20&" "&E20&" "&C20) -> Sample Learner015 | I20: =IF(H20="","",DATEDIF(H20,TODAY(),"Y")) | J20: Kinder | K20: KAMAGONG | L20: Kinder Adviser | M20: 2026-2027 | N20: Active | O20: 46230 | S20: For LIS Verification | T20: 46230 | U20: Placeholder / Replace with LIS Export | W20: =IF(B20="","Missing LRN",IF(OR(J20="",K20=""),"Missing Grade/Section","OK")) -> OK
A21: 16 | B21: For LRN Verification - Grade 1-131 | C21: AKABO | D21: RONEL F. | F21: =TRIM(D21&" "&E21&" "&C21) -> RONEL F. AKABO | G21: Male | I21: =IF(H21="","",DATEDIF(H21,TODAY(),"Y")) | J21: Grade 1 | K21: MAGKONO | L21: Jenny Queen L. Orillaneda | M21: 2026-2027 | N21: Active | O21: 46230 | S21: Name imported from MPS template | T21: 46230 | U21: GRADE-I-1ST-SUMMATIVE-MPS.xlsx | V21: Student name imported from assessment/MPS file. Official LRN, birthdate, guardian, and address still need SF1/LIS verification. | W21: Needs official LRN verification
A22: 17 | B22: For LRN Verification - Grade 1-131 | C22: AKABO | D22: ROWEL F. | F22: =TRIM(D22&" "&E22&" "&C22) -> ROWEL F. AKABO | G22: Male | I22: =IF(H22="","",DATEDIF(H22,TODAY(),"Y")) | J22: Grade 1 | K22: MAGKONO | L22: Jenny Queen L. Orillaneda | M22: 2026-2027 | N22: Active | O22: 46230 | S22: Name imported from MPS template | T22: 46230 | U22: GRADE-I-1ST-SUMMATIVE-MPS.xlsx | V22: Student name imported from assessment/MPS file. Official LRN, birthdate, guardian, and address still need SF1/LIS verification. | W22: Needs official LRN verification
A23: 18 | B23: For LRN Verification - Grade 1-131 | C23: BAUTISTA | D23: DARYL JR. | F23: =TRIM(D23&" "&E23&" "&C23) -> DARYL JR. BAUTISTA | G23: Male | I23: =IF(H23="","",DATEDIF(H23,TODAY(),"Y")) | J23: Grade 1 | K23: MAGKONO | L23: Jenny Queen L. Orillaneda | M23: 2026-2027 | N23: Active | O23: 46230 | S23: Name imported from MPS template | T23: 46230 | U23: GRADE-I-1ST-SUMMATIVE-MPS.xlsx | V23: Student name imported from assessment/MPS file. Official LRN, birthdate, guardian, and address still need SF1/LIS verification. | W23: Needs official LRN verification
A24: 19 | B24: For LRN Verification - Grade 1-131 | C24: CAÑESO | D24: RUILY D. | F24: =TRIM(D24&" "&E24&" "&C24) -> RUILY D. CAÑESO | G24: Male | I24: =IF(H24="","",DATEDIF(H24,TODAY(),"Y")) | J24: Grade 1 | K24: MAGKONO | L24: Jenny Queen L. Orillaneda | M24: 2026-2027 | N24: Active | O24: 46230 | S24: Name imported from MPS template | T24: 46230 | U24: GRADE-I-1ST-SUMMATIVE-MPS.xlsx | V24: Student name imported from assessment/MPS file. Official LRN, birthdate, guardian, and address still need SF1/LIS verification. | W24: Needs official LRN verification
A25: 20 | B25: For LRN Verification - Grade 1-131 | C25: LANANG | D25: ALJUN C. | F25: =TRIM(D25&" "&E25&" "&C25) -> ALJUN C. LANANG | G25: Male | I25: =IF(H25="","",DATEDIF(H25,TODAY(),"Y")) | J25: Grade 1 | K25: MAGKONO | L25: Jenny Queen L. Orillaneda | M25: 2026-2027 | N25: Active | O25: 46230 | S25: Name imported from MPS template | T25: 46230 | U25: GRADE-I-1ST-SUMMATIVE-MPS.xlsx | V25: Student name imported from assessment/MPS file. Official LRN, birthdate, guardian, and address still need SF1/LIS verification. | W25: Needs official LRN verification
A26: 21 | B26: For LRN Verification - Grade 1-131 | C26: LANANG | D26: MARVIN O. | F26: =TRIM(D26&" "&E26&" "&C26) -> MARVIN O. LANANG | G26: Male | I26: =IF(H26="","",DATEDIF(H26,TODAY(),"Y")) | J26: Grade 1 | K26: MAGKONO | L26: Jenny Queen L. Orillaneda | M26: 2026-2027 | N26: Active | O26: 46230 | S26: Name imported from MPS template | T26: 46230 | U26: GRADE-I-1ST-SUMMATIVE-MPS.xlsx | V26: Student name imported from assessment/MPS file. Official LRN, birthdate, guardian, and address still need SF1/LIS verification. | W26: Needs official LRN verification
A27: 22 | B27: For LRN Verification - Grade 1-131 | C27: LOGRONIO | D27: LARCON M. | F27: =TRIM(D27&" "&E27&" "&C27) -> LARCON M. LOGRONIO | G27: Male | I27: =IF(H27="","",DATEDIF(H27,TODAY(),"Y")) | J27: Grade 1 | K27: MAGKONO | L27: Jenny Queen L. Orillaneda | M27: 2026-2027 | N27: Active | O27: 46230 | S27: Name imported from MPS template | T27: 46230 | U27: GRADE-I-1ST-SUMMATIVE-MPS.xlsx | V27: Student name imported from assessment/MPS file. Official LRN, birthdate, guardian, and address still need SF1/LIS verification. | W27: Needs official LRN verification
A28: 23 | B28: For LRN Verification - Grade 1-131 | C28: RIVAS | D28: LEO JOHN M. | F28: =TRIM(D28&" "&E28&" "&C28) -> LEO JOHN M. RIVAS | G28: Male | I28: =IF(H28="","",DATEDIF(H28,TODAY(),"Y")) | J28: Grade 1 | K28: MAGKONO | L28: Jenny Queen L. Orillaneda | M28: 2026-2027 | N28: Active | O28: 46230 | S28: Name imported from MPS template | T28: 46230 | U28: GRADE-I-1ST-SUMMATIVE-MPS.xlsx | V28: Student name imported from assessment/MPS file. Official LRN, birthdate, guardian, and address still need SF1/LIS verification. | W28: Needs official LRN verification
A29: 24 | B29: For LRN Verification - Grade 1-131 | C29: TAÑOLA | D29: JONATHAN JR. | F29: =TRIM(D29&" "&E29&" "&C29) -> JONATHAN JR. TAÑOLA | G29: Male | I29: =IF(H29="","",DATEDIF(H29,TODAY(),"Y")) | J29: Grade 1 | K29: MAGKONO | L29: Jenny Queen L. Orillaneda | M29: 2026-2027 | N29: Active | O29: 46230 | S29: Name imported from MPS template | T29: 46230 | U29: GRADE-I-1ST-SUMMATIVE-MPS.xlsx | V29: Student name imported from assessment/MPS file. Official LRN, birthdate, guardian, and address still need SF1/LIS verification. | W29: Needs official LRN verification
A30: 25 | B30: For LRN Verification - Grade 1-131 | C30: TANOLA | D30: NELMAR L. | F30: =TRIM(D30&" "&E30&" "&C30) -> NELMAR L. TANOLA | G30: Male | I30: =IF(H30="","",DATEDIF(H30,TODAY(),"Y")) | J30: Grade 1 | K30: MAGKONO | L30: Jenny Queen L. Orillaneda | M30: 2026-2027 | N30: Active | O30: 46230 | S30: Name imported from MPS template | T30: 46230 | U30: GRADE-I-1ST-SUMMATIVE-MPS.xlsx | V30: Student name imported from assessment/MPS file. Official LRN, birthdate, guardian, and address still need SF1/LIS verification. | W30: Needs official LRN verification
A31: 26 | B31: For LRN Verification - Grade 1-131 | C31: ALMONTE | D31: CHRISTINE MAE M. | F31: =TRIM(D31&" "&E31&" "&C31) -> CHRISTINE MAE M. ALMONTE | G31: Female | I31: =IF(H31="","",DATEDIF(H31,TODAY(),"Y")) | J31: Grade 1 | K31: MAGKONO | L31: Jenny Queen L. Orillaneda | M31: 2026-2027 | N31: Active | O31: 46230 | S31: Name imported from MPS template | T31: 46230 | U31: GRADE-I-1ST-SUMMATIVE-MPS.xlsx | V31: Student name imported from assessment/MPS file. Official LRN, birthdate, guardian, and address still need SF1/LIS verification. | W31: Needs official LRN verification
A32: 27 | B32: For LRN Verification - Grade 1-131 | C32: CAÑESO | D32: ASHLEY D | F32: =TRIM(D32&" "&E32&" "&C32) -> ASHLEY D CAÑESO | G32: Female | I32: =IF(H32="","",DATEDIF(H32,TODAY(),"Y")) | J32: Grade 1 | K32: MAGKONO | L32: Jenny Queen L. Orillaneda | M32: 2026-2027 | N32: Active | O32: 46230 | S32: Name imported from MPS template | T32: 46230 | U32: GRADE-I-1ST-SUMMATIVE-MPS.xlsx | V32: Student name imported from assessment/MPS file. Official LRN, birthdate, guardian, and address still need SF1/LIS verification. | W32: Needs official LRN verification
... A55: 50 | B55: For LRN Verification - Grade 2-131 | C55: TOBIANO | D55: PRINCESS SOFIA B. | F55: =TRIM(D55&" "&E55&" "&C55) -> PRINCESS SOFIA B. TOBIANO | G55: Female | I55: =IF(H55="","",DATEDIF(H55,TODAY(),"Y")) | J55: Grade 2 | K55: NARRA | L55: Maria Fatima R. Peñanueva | M55: 2026-2027 | N55: Active | O55: 46230 | S55: Name imported from MPS template | T55: 46230 | U55: GRADE-2-1ST-SUMMATIVE-MPS.xlsx | V55: Student name imported from assessment/MPS file. Official LRN, birthdate, guardian, and address still need SF1/LIS verification. | W55: Needs official LRN verification
A56: 51 | B56: LRN-000000000051 | C56: Learner051 | D56: Sample | F56: =TRIM(D56&" "&E56&" "&C56) -> Sample Learner051 | I56: =IF(H56="","",DATEDIF(H56,TODAY(),"Y")) | J56: Grade 2 | K56: NARRA | L56: Maria Fatima R. Peñanueva | M56: 2026-2027 | N56: Active | O56: 46230 | S56: No name in uploaded MPS file | T56: 46230 | U56: Placeholder pending official SF1/LIS | W56: Placeholder / Needs student name
A57: 52 | B57: LRN-000000000052 | C57: Learner052 | D57: Sample | F57: =TRIM(D57&" "&E57&" "&C57) -> Sample Learner052 | I57: =IF(H57="","",DATEDIF(H57,TODAY(),"Y")) | J57: Grade 2 | K57: NARRA | L57: Maria Fatima R. Peñanueva | M57: 2026-2027 | N57: Active | O57: 46230 | S57: No name in uploaded MPS file | T57: 46230 | U57: Placeholder pending official SF1/LIS | W57: Placeholder / Needs student name
A58: 53 | B58: LRN-000000000053 | C58: Learner053 | D58: Sample | F58: =TRIM(D58&" "&E58&" "&C58) -> Sample Learner053 | I58: =IF(H58="","",DATEDIF(H58,TODAY(),"Y")) | J58: Grade 2 | K58: NARRA | L58: Maria Fatima R. Peñanueva | M58: 2026-2027 | N58: Active | O58: 46230 | S58: No name in uploaded MPS file | T58: 46230 | U58: Placeholder pending official SF1/LIS | W58: Placeholder / Needs student name
A59: 54 | B59: LRN-000000000054 | C59: Learner054 | D59: Sample | F59: =TRIM(D59&" "&E59&" "&C59) -> Sample Learner054 | I59: =IF(H59="","",DATEDIF(H59,TODAY(),"Y")) | J59: Grade 2 | K59: NARRA | L59: Maria Fatima R. Peñanueva | M59: 2026-2027 | N59: Active | O59: 46230 | S59: No name in uploaded MPS file | T59: 46230 | U59: Placeholder pending official SF1/LIS | W59: Placeholder / Needs student name
A60: 55 | B60: LRN-000000000055 | C60: Learner055 | D60: Sample | F60: =TRIM(D60&" "&E60&" "&C60) -> Sample Learner055 | I60: =IF(H60="","",DATEDIF(H60,TODAY(),"Y")) | J60: Grade 2 | K60: NARRA | L60: Maria Fatima R. Peñanueva | M60: 2026-2027 | N60: Active | O60: 46230 | S60: No name in uploaded MPS file | T60: 46230 | U60: Placeholder pending official SF1/LIS | W60: Placeholder / Needs student name
A61: 56 | B61: LRN-000000000056 | C61: Learner056 | D61: Sample | F61: =TRIM(D61&" "&E61&" "&C61) -> Sample Learner056 | I61: =IF(H61="","",DATEDIF(H61,TODAY(),"Y")) | J61: Grade 3 | K61: TOOG | L61: Jessa Mae R. Flores | M61: 2026-2027 | N61: Active | O61: 46230 | S61: For LIS Verification | T61: 46230 | U61: Placeholder / Replace with LIS Export | W61: =IF(B61="","Missing LRN",IF(OR(J61="",K61=""),"Missing Grade/Section","OK")) -> OK
A62: 57 | B62: LRN-000000000057 | C62: Learner057 | D62: Sample | F62: =TRIM(D62&" "&E62&" "&C62) -> Sample Learner057 | I62: =IF(H62="","",DATEDIF(H62,TODAY(),"Y")) | J62: Grade 3 | K62: TOOG | L62: Jessa Mae R. Flores | M62: 2026-2027 | N62: Active | O62: 46230 | S62: For LIS Verification | T62: 46230 | U62: Placeholder / Replace with LIS Export | W62: =IF(B62="","Missing LRN",IF(OR(J62="",K62=""),"Missing Grade/Section","OK")) -> OK
A63: 58 | B63: LRN-000000000058 | C63: Learner058 | D63: Sample | F63: =TRIM(D63&" "&E63&" "&C63) -> Sample Learner058 | I63: =IF(H63="","",DATEDIF(H63,TODAY(),"Y")) | J63: Grade 3 | K63: TOOG | L63: Jessa Mae R. Flores | M63: 2026-2027 | N63: Active | O63: 46230 | S63: For LIS Verification | T63: 46230 | U63: Placeholder / Replace with LIS Export | W63: =IF(B63="","Missing LRN",IF(OR(J63="",K63=""),"Missing Grade/Section","OK")) -> OK
A64: 59 | B64: LRN-000000000059 | C64: Learner059 | D64: Sample | F64: =TRIM(D64&" "&E64&" "&C64) -> Sample Learner059 | I64: =IF(H64="","",DATEDIF(H64,TODAY(),"Y")) | J64: Grade 3 | K64: TOOG | L64: Jessa Mae R. Flores | M64: 2026-2027 | N64: Active | O64: 46230 | S64: For LIS Verification | T64: 46230 | U64: Placeholder / Replace with LIS Export | W64: =IF(B64="","Missing LRN",IF(OR(J64="",K64=""),"Missing Grade/Section","OK")) -> OK
A65: 60 | B65: LRN-000000000060 | C65: Learner060 | D65: Sample | F65: =TRIM(D65&" "&E65&" "&C65) -> Sample Learner060 | I65: =IF(H65="","",DATEDIF(H65,TODAY(),"Y")) | J65: Grade 3 | K65: TOOG | L65: Jessa Mae R. Flores | M65: 2026-2027 | N65: Active | O65: 46230 | S65: For LIS Verification | T65: 46230 | U65: Placeholder / Replace with LIS Export | W65: =IF(B65="","Missing LRN",IF(OR(J65="",K65=""),"Missing Grade/Section","OK")) -> OK
A66: 61 | B66: LRN-000000000061 | C66: Learner061 | D66: Sample | F66: =TRIM(D66&" "&E66&" "&C66) -> Sample Learner061 | I66: =IF(H66="","",DATEDIF(H66,TODAY(),"Y")) | J66: Grade 3 | K66: TOOG | L66: Jessa Mae R. Flores | M66: 2026-2027 | N66: Active | O66: 46230 | S66: For LIS Verification | T66: 46230 | U66: Placeholder / Replace with LIS Export | W66: =IF(B66="","Missing LRN",IF(OR(J66="",K66=""),"Missing Grade/Section","OK")) -> OK
A67: 62 | B67: LRN-000000000062 | C67: Learner062 | D67: Sample | F67: =TRIM(D67&" "&E67&" "&C67) -> Sample Learner062 | I67: =IF(H67="","",DATEDIF(H67,TODAY(),"Y")) | J67: Grade 3 | K67: TOOG | L67: Jessa Mae R. Flores | M67: 2026-2027 | N67: Active | O67: 46230 | S67: For LIS Verification | T67: 46230 | U67: Placeholder / Replace with LIS Export | W67: =IF(B67="","Missing LRN",IF(OR(J67="",K67=""),"Missing Grade/Section","OK")) -> OK
...

Sheet Student_Data_Instructions
A1: HOW TO UPDATE STUDENT DATA Use this guide when encoding or importing official LIS student/enrollment data.
A5: Step | B5: Action | C5: Where | D5: Important Rule | E5: Result
A6: 1 | B6: Download/export learner list from LIS | C6: LIS portal | D6: Use LRN as unique key | E6: Official student source file
A7: 2 | B7: Open Student_Masterlist | C7: This workbook | D7: Do not delete formula columns | E7: Ready to paste/update student data
A8: 3 | B8: Replace placeholder learner data | C8: Rows 6 onward | D8: Keep grade/section official names | E8: Student data becomes school-specific
A9: 4 | B9: Check DataCheck column | C9: Column W | D9: Must show OK | E9: Data is ready for dashboard
A10: 5 | B10: Use Enrollment_Dashboard | C10: Dashboard sheet | D10: Refresh workbook/calculations if needed | E10: Enrollment counts update
A11: 6 | B11: Do not delete old learners immediately | C11: EnrollmentStatus column | D11: Use For Verification first | E11: Protect historical records
A14: Note: I added placeholder learner records because actual names/LRNs were not provided. Replace placeholder names and LRN values with your official LIS export data. Use Class_Sections as the official class reference.

Sheet Student_Import_Log
A1: DateImported | B1: SourceFile | C1: GradeLevel | D1: Section | E1: RecordsImported | F1: ImportedFields | G1: Notes
A2: 46230 | B2: TEMPLATE_G5-MPS_TERM-1-SUMMATIVE-TEST-1_SY-2026-2027.xlsx | C2: Grade 5 | D2: LAUAAN | E2: 21 | F2: Learner names only | G2: LRN/sex/birthdate not present in the MPS template; confirm using populated SF1/LIS.
A3: 46230 | B3: GRADE-I-1ST-SUMMATIVE-MPS.xlsx | C3: Grade 1 | D3: MAGKONO | E3: 20 | F3: Learner names; sex where present in Grade 1/2 file | G3: LRN/birthdate/guardian/address still require populated SF1/LIS.
A4: 46230 | B4: GRADE-2-1ST-SUMMATIVE-MPS.xlsx | C4: Grade 2 | D4: NARRA | E4: 15 | F4: Learner names; sex where present in Grade 1/2 file | G4: LRN/birthdate/guardian/address still require populated SF1/LIS.
A5: 46230 | B5: MPS_TERM-1-SUMMATIVE-TEST-1_GRADE-4-SY-2026-2027.xlsx | C5: Grade 4 | D5: TUGAS | E5: 16 | F5: Learner names; sex where present in Grade 1/2 file | G5: LRN/birthdate/guardian/address still require populated SF1/LIS.
A6: 46230 | B6: TEMPLATE_G5-MPS_TERM-1-SUMMATIVE-TEST-1_SY-2026-2027.xlsx | C6: Grade 5 | D6: LAUAAN | E6: 21 | F6: Learner names; sex where present in Grade 1/2 file | G6: LRN/birthdate/guardian/address still require populated SF1/LIS.
A7: 46230 | B7: TEMPLATE_G6-MPS_TERM-1-SUMMATIVE-TEST-1_SY-2026-2027.xlsx | C7: Grade 6 | D7: YAKAL | E7: 33 | F7: Learner names; sex where present in Grade 1/2 file | G7: LRN/birthdate/guardian/address still require populated SF1/LIS.

Sheet Class_Sections
A1: OFFICIAL LIST OF CLASSES AND SECTIONS
A4: GradeLevel | B4: Section | C4: DisplayName | D4: Status | E4: Notes
A5: Kinder | B5: KAMAGONG | C5: Kinder - KAMAGONG | D5: Active | E5: From LIS class list image
A6: Grade 1 | B6: MAGKONO | C6: Grade 1 - MAGKONO | D6: Active | E6: From LIS class list image
A7: Grade 2 | B7: NARRA | C7: Grade 2 - NARRA | D7: Active | E7: From LIS class list image
A8: Grade 3 | B8: TOOG | C8: Grade 3 - TOOG | D8: Active | E8: From LIS class list image
A9: Grade 4 | B9: TUGAS | C9: Grade 4 - TUGAS | D9: Active | E9: From LIS class list image
A10: Grade 5 | B10: LAUAAN | C10: Grade 5 - LAUAAN | D10: Active | E10: From LIS class list image
A11: Grade 6 | B11: YAKAL | C11: Grade 6 - YAKAL | D11: Active | E11: From LIS class list image

Sheet Teacher_View_Dashboard
A1: TEACHER VIEW-ONLY DASHBOARD Designed for teachers to view submission updates and class results without editing the database. | AA1: Metric | AB1: Value
AA2: Submissions | AB2: =COUNTIF(Assessment_Submissions!C:C,$B$5) -> 1
AA3: Learner Rows | AB3: =COUNTIF(Learner_Scores!D:D,$B$5) -> 5
AA4: Average MPS | AB4: =IFERROR(AVERAGEIF(Learner_Scores!D:D,$B$5,Learner_Scores!O:O),0) -> 0.724
A5: Select Teacher: | B5: Jenny Queen L. Orillaneda | D5: Role: | E5: =IFERROR(_xludf.xlookup(B5,Access_Control!B:B,Access_Control!D:D),"") | G5: Assigned Class: | H5: =IFERROR(_xludf.xlookup(B5,Access_Control!B:B,Access_Control!E:E)&" - "&_xludf.xlookup(B5,Access_Control!B:B,Access_Control!F:F),"") | AA5: Proficient Count | AB5: =COUNTIFS(Learner_Scores!D:D,$B$5,Learner_Scores!P:P,"Proficient") -> 2
AA6: For Checking | AB6: =COUNTIFS(Assessment_Submissions!C:C,$B$5,Assessment_Submissions!S:S,"For Checking") -> 1
A7: TOTAL SUBMISSIONS | D7: LEARNER RESULTS | G7: AVERAGE MPS | J7: FOR CHECKING | M7: RETURNED | AA7: Returned | AB7: =COUNTIFS(Assessment_Submissions!C:C,$B$5,Assessment_Submissions!S:S,"Returned") -> 0
B8: =AB2 -> 1 | E8: =AB3 -> 5 | H8: =AB4 -> 0.724 | K8: =AB6 -> 1 | N8: =AB7 -> 0 | AA8: Submitted Accepted | AB8: =COUNTIFS(Assessment_Submissions!C:C,$B$5,Assessment_Submissions!S:S,"Submitted") -> 0
AA9: Teacher Email | AB9: =IFERROR(_xludf.xlookup($B$5,Access_Control!B:B,Access_Control!C:C),"")
A10: Submitted through Forms/upload | D10: Rows extracted from Excel | G10: Class result summary | J10: Waiting for admin review | M10: Needs correction
A13: MY RECENT SUBMISSIONS AND REPORT FILES
A14: Date | B14: Quarter | C14: Assessment | D14: Subject | E14: Mean Score | F14: MPS | G14: Status | H14: File | I14: Remarks
A15: =_xludf.filter(CHOOSE({1,2,3,4,5,6,7,8,9},Assessment_Submissions!B5:B200,Assessment_Submissions!F5:F200,Assessment_Submissions!G5:G200,Assessment_Submissions!H5:H200,Assessment_Submissions!K5:K200,Assessment_Submissions!L5:L200,Assessment_Submissions!S5:S200,Assessment_Submissions!R5:R200,Assessment_Submissions!T5:T200),Assessment_Submissions!C5:C200=$B$5,"No submissions yet") -> #NAME?
A25: MY EXTRACTED LEARNER RESULTS
A26: LRN | B26: Learner Name | C26: Grade | D26: Section | E26: Assessment | F26: Subject | G26: Total Items | H26: Raw Score | I26: MPS | J26: Performance | K26: Status
A27: =_xludf.filter(CHOOSE({1,2,3,4,5,6,7,8,9,10,11},Learner_Scores!K6:K300,Learner_Scores!L6:L300,Learner_Scores!F6:F300,Learner_Scores!G6:G300,Learner_Scores!I6:I300,Learner_Scores!J6:J300,Learner_Scores!M6:M300,Learner_Scores!N6:N300,Learner_Scores!O6:O300,Learner_Scores!P6:P300,Learner_Scores!T6:T300),Learner_Scores!D6:D300=$B$5,"No extracted learner scores yet") -> #NAME?
A43: SUBJECT SUMMARY
A44: Subject | B44: Rows | C44: Average MPS | D44: Proficient | E44: Nearly Proficient | F44: Low/Not Proficient
A45: English | B45: =COUNTIFS(Learner_Scores!D:D,$B$5,Learner_Scores!J:J,A45) -> 5 | C45: =IFERROR(AVERAGEIFS(Learner_Scores!O:O,Learner_Scores!D:D,$B$5,Learner_Scores!J:J,A45),0) -> 0.724 | D45: =COUNTIFS(Learner_Scores!D:D,$B$5,Learner_Scores!J:J,A45,Learner_Scores!P:P,"Proficient") -> 2 | E45: =COUNTIFS(Learner_Scores!D:D,$B$5,Learner_Scores!J:J,A45,Learner_Scores!P:P,"Nearly Proficient") -> 3 | F45: =COUNTIFS(Learner_Scores!D:D,$B$5,Learner_Scores!J:J,A45,Learner_Scores!P:P,"Low Proficient") + COUNTIFS(Learner_Scores!D:D,$B$5,Learner_Scores!J:J,A45,Learner_Scores!P:P,"Not Proficient") -> 0
A46: Filipino | B46: =COUNTIFS(Learner_Scores!D:D,$B$5,Learner_Scores!J:J,A46) -> 0 | C46: =IFERROR(AVERAGEIFS(Learner_Scores!O:O,Learner_Scores!D:D,$B$5,Learner_Scores!J:J,A46),0) -> 0 | D46: =COUNTIFS(Learner_Scores!D:D,$B$5,Learner_Scores!J:J,A46,Learner_Scores!P:P,"Proficient") -> 0 | E46: =COUNTIFS(Learner_Scores!D:D,$B$5,Learner_Scores!J:J,A46,Learner_Scores!P:P,"Nearly Proficient") -> 0 | F46: =COUNTIFS(Learner_Scores!D:D,$B$5,Learner_Scores!J:J,A46,Learner_Scores!P:P,"Low Proficient") + COUNTIFS(Learner_Scores!D:D,$B$5,Learner_Scores!J:J,A46,Learner_Scores!P:P,"Not Proficient") -> 0
A47: Mathematics | B47: =COUNTIFS(Learner_Scores!D:D,$B$5,Learner_Scores!J:J,A47) -> 0 | C47: =IFERROR(AVERAGEIFS(Learner_Scores!O:O,Learner_Scores!D:D,$B$5,Learner_Scores!J:J,A47),0) -> 0 | D47: =COUNTIFS(Learner_Scores!D:D,$B$5,Learner_Scores!J:J,A47,Learner_Scores!P:P,"Proficient") -> 0 | E47: =COUNTIFS(Learner_Scores!D:D,$B$5,Learner_Scores!J:J,A47,Learner_Scores!P:P,"Nearly Proficient") -> 0 | F47: =COUNTIFS(Learner_Scores!D:D,$B$5,Learner_Scores!J:J,A47,Learner_Scores!P:P,"Low Proficient") + COUNTIFS(Learner_Scores!D:D,$B$5,Learner_Scores!J:J,A47,Learner_Scores!P:P,"Not Proficient") -> 0
A48: Science | B48: =COUNTIFS(Learner_Scores!D:D,$B$5,Learner_Scores!J:J,A48) -> 0 | C48: =IFERROR(AVERAGEIFS(Learner_Scores!O:O,Learner_Scores!D:D,$B$5,Learner_Scores!J:J,A48),0) -> 0 | D48: =COUNTIFS(Learner_Scores!D:D,$B$5,Learner_Scores!J:J,A48,Learner_Scores!P:P,"Proficient") -> 0 | E48: =COUNTIFS(Learner_Scores!D:D,$B$5,Learner_Scores!J:J,A48,Learner_Scores!P:P,"Nearly Proficient") -> 0 | F48: =COUNTIFS(Learner_Scores!D:D,$B$5,Learner_Scores!J:J,A48,Learner_Scores!P:P,"Low Proficient") + COUNTIFS(Learner_Scores!D:D,$B$5,Learner_Scores!J:J,A48,Learner_Scores!P:P,"Not Proficient") -> 0
A49: GMRC | B49: =COUNTIFS(Learner_Scores!D:D,$B$5,Learner_Scores!J:J,A49) -> 0 | C49: =IFERROR(AVERAGEIFS(Learner_Scores!O:O,Learner_Scores!D:D,$B$5,Learner_Scores!J:J,A49),0) -> 0 | D49: =COUNTIFS(Learner_Scores!D:D,$B$5,Learner_Scores!J:J,A49,Learner_Scores!P:P,"Proficient") -> 0 | E49: =COUNTIFS(Learner_Scores!D:D,$B$5,Learner_Scores!J:J,A49,Learner_Scores!P:P,"Nearly Proficient") -> 0 | F49: =COUNTIFS(Learner_Scores!D:D,$B$5,Learner_Scores!J:J,A49,Learner_Scores!P:P,"Low Proficient") + COUNTIFS(Learner_Scores!D:D,$B$5,Learner_Scores!J:J,A49,Learner_Scores!P:P,"Not Proficient") -> 0
A50: Readiness | B50: =COUNTIFS(Learner_Scores!D:D,$B$5,Learner_Scores!J:J,A50) -> 0 | C50: =IFERROR(AVERAGEIFS(Learner_Scores!O:O,Learner_Scores!D:D,$B$5,Learner_Scores!J:J,A50),0) -> 0 | D50: =COUNTIFS(Learner_Scores!D:D,$B$5,Learner_Scores!J:J,A50,Learner_Scores!P:P,"Proficient") -> 0 | E50: =COUNTIFS(Learner_Scores!D:D,$B$5,Learner_Scores!J:J,A50,Learner_Scores!P:P,"Nearly Proficient") -> 0 | F50: =COUNTIFS(Learner_Scores!D:D,$B$5,Learner_Scores!J:J,A50,Learner_Scores!P:P,"Low Proficient") + COUNTIFS(Learner_Scores!D:D,$B$5,Learner_Scores!J:J,A50,Learner_Scores!P:P,"Not Proficient") -> 0
A62: Teacher View Note: Share this dashboard as View Only through SharePoint/OneDrive or publish it to Power BI. Teachers should submit Excel result files through Microsoft Forms only. Do not give teachers edit access to the main workbook.

Sheet Learner_Scores
A1: LEARNER SCORES EXTRACTED FROM TEACHER EXCEL UPLOADS Power Automate copies every learner row from the teacher template into this table.
A5: ScoreID | B5: SubmissionID | C5: SubmissionDate | D5: TeacherName | E5: TeacherEmail | F5: GradeLevel | G5: Section | H5: Quarter | I5: AssessmentType | J5: Subject | K5: LRN | L5: LearnerName | M5: TotalItems | N5: RawScore | O5: MPS | P5: PerformanceLevel | Q5: Remarks | R5: UploadedFileName | S5: UploadedFileLink | T5: Status
A6: 1 | B6: 1001 | C6: 46230.469 | D6: Jenny Queen L. Orillaneda | E6: jenny.teacher@deped.gov.ph | F6: Grade 1 | G6: MAGKONO | H6: 1st Quarter | I6: Periodical Exam | J6: English | K6: LRN-000000000001 | L6: Learner 001 | M6: 50 | N6: 36 | O6: =IFERROR(N6/M6,"") -> 0.72 | P6: =IF(O6="","",IF(O6>=0.75,"Proficient",IF(O6>=0.5,"Nearly Proficient",IF(O6>=0.25,"Low Proficient","Not Proficient")))) -> Nearly Proficient | R6: Grade 1_English_Result.xlsx | S6: https://contoso.sharepoint.com/sites/MAMON/Shared%20Documents/TeacherUploads/sample.xlsx | T6: For Checking
A7: 2 | B7: 1001 | C7: 46230.469 | D7: Jenny Queen L. Orillaneda | E7: jenny.teacher@deped.gov.ph | F7: Grade 1 | G7: MAGKONO | H7: 1st Quarter | I7: Periodical Exam | J7: English | K7: LRN-000000000002 | L7: Learner 002 | M7: 50 | N7: 38 | O7: =IFERROR(N7/M7,"") -> 0.76 | P7: =IF(O7="","",IF(O7>=0.75,"Proficient",IF(O7>=0.5,"Nearly Proficient",IF(O7>=0.25,"Low Proficient","Not Proficient")))) -> Proficient | R7: Grade 1_English_Result.xlsx | S7: https://contoso.sharepoint.com/sites/MAMON/Shared%20Documents/TeacherUploads/sample.xlsx | T7: For Checking
A8: 3 | B8: 1001 | C8: 46230.469 | D8: Jenny Queen L. Orillaneda | E8: jenny.teacher@deped.gov.ph | F8: Grade 1 | G8: MAGKONO | H8: 1st Quarter | I8: Periodical Exam | J8: English | K8: LRN-000000000003 | L8: Learner 003 | M8: 50 | N8: 32 | O8: =IFERROR(N8/M8,"") -> 0.64 | P8: =IF(O8="","",IF(O8>=0.75,"Proficient",IF(O8>=0.5,"Nearly Proficient",IF(O8>=0.25,"Low Proficient","Not Proficient")))) -> Nearly Proficient | R8: Grade 1_English_Result.xlsx | S8: https://contoso.sharepoint.com/sites/MAMON/Shared%20Documents/TeacherUploads/sample.xlsx | T8: For Checking
A9: 4 | B9: 1001 | C9: 46230.469 | D9: Jenny Queen L. Orillaneda | E9: jenny.teacher@deped.gov.ph | F9: Grade 1 | G9: MAGKONO | H9: 1st Quarter | I9: Periodical Exam | J9: English | K9: LRN-000000000004 | L9: Learner 004 | M9: 50 | N9: 40 | O9: =IFERROR(N9/M9,"") -> 0.8 | P9: =IF(O9="","",IF(O9>=0.75,"Proficient",IF(O9>=0.5,"Nearly Proficient",IF(O9>=0.25,"Low Proficient","Not Proficient")))) -> Proficient | R9: Grade 1_English_Result.xlsx | S9: https://contoso.sharepoint.com/sites/MAMON/Shared%20Documents/TeacherUploads/sample.xlsx | T9: For Checking
A10: 5 | B10: 1001 | C10: 46230.469 | D10: Jenny Queen L. Orillaneda | E10: jenny.teacher@deped.gov.ph | F10: Grade 1 | G10: MAGKONO | H10: 1st Quarter | I10: Periodical Exam | J10: English | K10: LRN-000000000005 | L10: Learner 005 | M10: 50 | N10: 35 | O10: =IFERROR(N10/M10,"") -> 0.7 | P10: =IF(O10="","",IF(O10>=0.75,"Proficient",IF(O10>=0.5,"Nearly Proficient",IF(O10>=0.25,"Low Proficient","Not Proficient")))) -> Nearly Proficient | R10: Grade 1_English_Result.xlsx | S10: https://contoso.sharepoint.com/sites/MAMON/Shared%20Documents/TeacherUploads/sample.xlsx | T10: For Checking
A11: 6 | B11: 1002 | C11: 46230.385 | D11: Maria Fatima R. Peñanueva | E11: maria.teacher@deped.gov.ph | F11: Grade 2 | G11: NARRA | H11: 1st Quarter | I11: Summative Test | J11: Mathematics | K11: LRN-000000000006 | L11: Learner 006 | M11: 40 | N11: 21 | O11: =IFERROR(N11/M11,"") -> 0.525 | P11: =IF(O11="","",IF(O11>=0.75,"Proficient",IF(O11>=0.5,"Nearly Proficient",IF(O11>=0.25,"Low Proficient","Not Proficient")))) -> Nearly Proficient | R11: Grade 2_Mathematics_Result.xlsx | S11: https://contoso.sharepoint.com/sites/MAMON/Shared%20Documents/TeacherUploads/sample.xlsx | T11: For Checking
A12: 7 | B12: 1002 | C12: 46230.385 | D12: Maria Fatima R. Peñanueva | E12: maria.teacher@deped.gov.ph | F12: Grade 2 | G12: NARRA | H12: 1st Quarter | I12: Summative Test | J12: Mathematics | K12: LRN-000000000007 | L12: Learner 007 | M12: 40 | N12: 25 | O12: =IFERROR(N12/M12,"") -> 0.625 | P12: =IF(O12="","",IF(O12>=0.75,"Proficient",IF(O12>=0.5,"Nearly Proficient",IF(O12>=0.25,"Low Proficient","Not Proficient")))) -> Nearly Proficient | R12: Grade 2_Mathematics_Result.xlsx | S12: https://contoso.sharepoint.com/sites/MAMON/Shared%20Documents/TeacherUploads/sample.xlsx | T12: For Checking
A13: 8 | B13: 1002 | C13: 46230.385 | D13: Maria Fatima R. Peñanueva | E13: maria.teacher@deped.gov.ph | F13: Grade 2 | G13: NARRA | H13: 1st Quarter | I13: Summative Test | J13: Mathematics | K13: LRN-000000000008 | L13: Learner 008 | M13: 40 | N13: 20 | O13: =IFERROR(N13/M13,"") -> 0.5 | P13: =IF(O13="","",IF(O13>=0.75,"Proficient",IF(O13>=0.5,"Nearly Proficient",IF(O13>=0.25,"Low Proficient","Not Proficient")))) -> Nearly Proficient | R13: Grade 2_Mathematics_Result.xlsx | S13: https://contoso.sharepoint.com/sites/MAMON/Shared%20Documents/TeacherUploads/sample.xlsx | T13: For Checking
A14: 9 | B14: 1002 | C14: 46230.385 | D14: Maria Fatima R. Peñanueva | E14: maria.teacher@deped.gov.ph | F14: Grade 2 | G14: NARRA | H14: 1st Quarter | I14: Summative Test | J14: Mathematics | K14: LRN-000000000009 | L14: Learner 009 | M14: 40 | N14: 18 | O14: =IFERROR(N14/M14,"") -> 0.45 | P14: =IF(O14="","",IF(O14>=0.75,"Proficient",IF(O14>=0.5,"Nearly Proficient",IF(O14>=0.25,"Low Proficient","Not Proficient")))) -> Low Proficient | R14: Grade 2_Mathematics_Result.xlsx | S14: https://contoso.sharepoint.com/sites/MAMON/Shared%20Documents/TeacherUploads/sample.xlsx | T14: For Checking
A15: 10 | B15: 1002 | C15: 46230.385 | D15: Maria Fatima R. Peñanueva | E15: maria.teacher@deped.gov.ph | F15: Grade 2 | G15: NARRA | H15: 1st Quarter | I15: Summative Test | J15: Mathematics | K15: LRN-000000000010 | L15: Learner 010 | M15: 40 | N15: 26 | O15: =IFERROR(N15/M15,"") -> 0.65 | P15: =IF(O15="","",IF(O15>=0.75,"Proficient",IF(O15>=0.5,"Nearly Proficient",IF(O15>=0.25,"Low Proficient","Not Proficient")))) -> Nearly Proficient | R15: Grade 2_Mathematics_Result.xlsx | S15: https://contoso.sharepoint.com/sites/MAMON/Shared%20Documents/TeacherUploads/sample.xlsx | T15: For Checking
A16: 11 | B16: 1003 | C16: 46230.427 | D16: Jessa Mae R. Flores | E16: jessa.teacher@deped.gov.ph | F16: Grade 3 | G16: TOOG | H16: 1st Quarter | I16: Periodical Exam | J16: Filipino | K16: LRN-000000000011 | L16: Learner 011 | M16: 30 | N16: 24 | O16: =IFERROR(N16/M16,"") -> 0.8 | P16: =IF(O16="","",IF(O16>=0.75,"Proficient",IF(O16>=0.5,"Nearly Proficient",IF(O16>=0.25,"Low Proficient","Not Proficient")))) -> Proficient | R16: Grade 3_Filipino_Result.xlsx | S16: https://contoso.sharepoint.com/sites/MAMON/Shared%20Documents/TeacherUploads/sample.xlsx | T16: For Checking
A17: 12 | B17: 1003 | C17: 46230.427 | D17: Jessa Mae R. Flores | E17: jessa.teacher@deped.gov.ph | F17: Grade 3 | G17: TOOG | H17: 1st Quarter | I17: Periodical Exam | J17: Filipino | K17: LRN-000000000012 | L17: Learner 012 | M17: 30 | N17: 25 | O17: =IFERROR(N17/M17,"") -> 0.83333333 | P17: =IF(O17="","",IF(O17>=0.75,"Proficient",IF(O17>=0.5,"Nearly Proficient",IF(O17>=0.25,"Low Proficient","Not Proficient")))) -> Proficient | R17: Grade 3_Filipino_Result.xlsx | S17: https://contoso.sharepoint.com/sites/MAMON/Shared%20Documents/TeacherUploads/sample.xlsx | T17: For Checking
... A20: 15 | B20: 1003 | C20: 46230.427 | D20: Jessa Mae R. Flores | E20: jessa.teacher@deped.gov.ph | F20: Grade 3 | G20: TOOG | H20: 1st Quarter | I20: Periodical Exam | J20: Filipino | K20: LRN-000000000015 | L20: Learner 015 | M20: 30 | N20: 21 | O20: =IFERROR(N20/M20,"") -> 0.7 | P20: =IF(O20="","",IF(O20>=0.75,"Proficient",IF(O20>=0.5,"Nearly Proficient",IF(O20>=0.25,"Low Proficient","Not Proficient")))) -> Nearly Proficient | R20: Grade 3_Filipino_Result.xlsx | S20: https://contoso.sharepoint.com/sites/MAMON/Shared%20Documents/TeacherUploads/sample.xlsx | T20: For Checking
O21: =IFERROR(N21/M21,"") | P21: =IF(O21="","",IF(O21>=0.75,"Proficient",IF(O21>=0.5,"Nearly Proficient",IF(O21>=0.25,"Low Proficient","Not Proficient"))))
O22: =IFERROR(N22/M22,"") | P22: =IF(O22="","",IF(O22>=0.75,"Proficient",IF(O22>=0.5,"Nearly Proficient",IF(O22>=0.25,"Low Proficient","Not Proficient"))))
O23: =IFERROR(N23/M23,"") | P23: =IF(O23="","",IF(O23>=0.75,"Proficient",IF(O23>=0.5,"Nearly Proficient",IF(O23>=0.25,"Low Proficient","Not Proficient"))))
O24: =IFERROR(N24/M24,"") | P24: =IF(O24="","",IF(O24>=0.75,"Proficient",IF(O24>=0.5,"Nearly Proficient",IF(O24>=0.25,"Low Proficient","Not Proficient"))))
O25: =IFERROR(N25/M25,"") | P25: =IF(O25="","",IF(O25>=0.75,"Proficient",IF(O25>=0.5,"Nearly Proficient",IF(O25>=0.25,"Low Proficient","Not Proficient"))))
O26: =IFERROR(N26/M26,"") | P26: =IF(O26="","",IF(O26>=0.75,"Proficient",IF(O26>=0.5,"Nearly Proficient",IF(O26>=0.25,"Low Proficient","Not Proficient"))))
O27: =IFERROR(N27/M27,"") | P27: =IF(O27="","",IF(O27>=0.75,"Proficient",IF(O27>=0.5,"Nearly Proficient",IF(O27>=0.25,"Low Proficient","Not Proficient"))))
O28: =IFERROR(N28/M28,"") | P28: =IF(O28="","",IF(O28>=0.75,"Proficient",IF(O28>=0.5,"Nearly Proficient",IF(O28>=0.25,"Low Proficient","Not Proficient"))))
O29: =IFERROR(N29/M29,"") | P29: =IF(O29="","",IF(O29>=0.75,"Proficient",IF(O29>=0.5,"Nearly Proficient",IF(O29>=0.25,"Low Proficient","Not Proficient"))))
O30: =IFERROR(N30/M30,"") | P30: =IF(O30="","",IF(O30>=0.75,"Proficient",IF(O30>=0.5,"Nearly Proficient",IF(O30>=0.25,"Low Proficient","Not Proficient"))))
O31: =IFERROR(N31/M31,"") | P31: =IF(O31="","",IF(O31>=0.75,"Proficient",IF(O31>=0.5,"Nearly Proficient",IF(O31>=0.25,"Low Proficient","Not Proficient"))))
O32: =IFERROR(N32/M32,"") | P32: =IF(O32="","",IF(O32>=0.75,"Proficient",IF(O32>=0.5,"Nearly Proficient",IF(O32>=0.25,"Low Proficient","Not Proficient"))))
... O300: =IFERROR(N300/M300,"") | P300: =IF(O300="","",IF(O300>=0.75,"Proficient",IF(O300>=0.5,"Nearly Proficient",IF(O300>=0.25,"Low Proficient","Not Proficient"))))

Sheet Assessment_Submissions
A1: ASSESSMENT SUBMISSIONS DATABASE This table receives Microsoft Forms responses through Power Automate.
A4: SubmissionID | B4: SubmissionDate | C4: TeacherName | D4: GradeLevel | E4: Section | F4: Quarter | G4: AssessmentType | H4: Subject | I4: TotalLearners | J4: TotalItems | K4: MeanScore | L4: MPS | M4: PerformanceLevel | N4: AtRiskLearners | O4: MasteredCompetency | P4: LeastMasteredCompetency | Q4: UploadedFileName | R4: UploadedFileLink | S4: Status | T4: Remarks
A5: 1001 | B5: 46230.389 | C5: Jenny Queen L. Orillaneda | D5: Grade 1 | E5: MAGKONO | F5: 1st Quarter | G5: Periodical Exam | H5: English | I5: 20 | J5: 50 | K5: 36 | L5: =IFERROR(K5/J5,0) -> 0.72 | M5: =IF(L5>=0.75,"Proficient",IF(L5>=0.5,"Nearly Proficient",IF(L5>=0.25,"Low Proficient","Not Proficient"))) -> Nearly Proficient | N5: 4 | O5: Polite expressions | P5: Letter-sound recognition | Q5: G1_English_Periodical.pdf | R5: https://contoso.sharepoint.com/sites/MAMON/Shared%20Documents/FormsUploads/G1_English_Periodical.pdf | S5: For Checking | T5: Sample only
A6: 1002 | B6: 46230.424 | C6: Maria Fatima R. Peñanueva | D6: Grade 2 | E6: NARRA | F6: 1st Quarter | G6: Summative Test | H6: Mathematics | I6: 20 | J6: 40 | K6: 21 | L6: =IFERROR(K6/J6,0) -> 0.525 | M6: =IF(L6>=0.75,"Proficient",IF(L6>=0.5,"Nearly Proficient",IF(L6>=0.25,"Low Proficient","Not Proficient"))) -> Nearly Proficient | N6: 8 | O6: Counting 1-100 | P6: Multi-step word math | Q6: G2_Math_Summative.xlsx | R6: https://contoso.sharepoint.com/sites/MAMON/Shared%20Documents/FormsUploads/G2_Math_Summative.xlsx | S6: For Checking | T6: Sample only
A7: 1003 | B7: 46230.479 | C7: Jessa Mae R. Flores | D7: Grade 3 | E7: TOOG | F7: 1st Quarter | G7: Diagnostic Test | H7: Filipino | I7: 20 | J7: 30 | K7: 24 | L7: =IFERROR(K7/J7,0) -> 0.8 | M7: =IF(L7>=0.75,"Proficient",IF(L7>=0.5,"Nearly Proficient",IF(L7>=0.25,"Low Proficient","Not Proficient"))) -> Proficient | N7: 2 | O7: Listening comprehension | P7: Written expression | Q7: G3_Filipino_Diagnostic.pdf | R7: https://contoso.sharepoint.com/sites/MAMON/Shared%20Documents/FormsUploads/G3_Filipino_Diagnostic.pdf | S7: Submitted | T7: Sample only
L8: =IFERROR(K8/J8,"") | M8: =IF(L8="","",IF(L8>=0.75,"Proficient",IF(L8>=0.5,"Nearly Proficient",IF(L8>=0.25,"Low Proficient","Not Proficient"))))
L9: =IFERROR(K9/J9,"") | M9: =IF(L9="","",IF(L9>=0.75,"Proficient",IF(L9>=0.5,"Nearly Proficient",IF(L9>=0.25,"Low Proficient","Not Proficient"))))
L10: =IFERROR(K10/J10,"") | M10: =IF(L10="","",IF(L10>=0.75,"Proficient",IF(L10>=0.5,"Nearly Proficient",IF(L10>=0.25,"Low Proficient","Not Proficient"))))
L11: =IFERROR(K11/J11,"") | M11: =IF(L11="","",IF(L11>=0.75,"Proficient",IF(L11>=0.5,"Nearly Proficient",IF(L11>=0.25,"Low Proficient","Not Proficient"))))
L12: =IFERROR(K12/J12,"") | M12: =IF(L12="","",IF(L12>=0.75,"Proficient",IF(L12>=0.5,"Nearly Proficient",IF(L12>=0.25,"Low Proficient","Not Proficient"))))
L13: =IFERROR(K13/J13,"") | M13: =IF(L13="","",IF(L13>=0.75,"Proficient",IF(L13>=0.5,"Nearly Proficient",IF(L13>=0.25,"Low Proficient","Not Proficient"))))
L14: =IFERROR(K14/J14,"") | M14: =IF(L14="","",IF(L14>=0.75,"Proficient",IF(L14>=0.5,"Nearly Proficient",IF(L14>=0.25,"Low Proficient","Not Proficient"))))
L15: =IFERROR(K15/J15,"") | M15: =IF(L15="","",IF(L15>=0.75,"Proficient",IF(L15>=0.5,"Nearly Proficient",IF(L15>=0.25,"Low Proficient","Not Proficient"))))
L16: =IFERROR(K16/J16,"") | M16: =IF(L16="","",IF(L16>=0.75,"Proficient",IF(L16>=0.5,"Nearly Proficient",IF(L16>=0.25,"Low Proficient","Not Proficient"))))
L17: =IFERROR(K17/J17,"") | M17: =IF(L17="","",IF(L17>=0.75,"Proficient",IF(L17>=0.5,"Nearly Proficient",IF(L17>=0.25,"Low Proficient","Not Proficient"))))
L18: =IFERROR(K18/J18,"") | M18: =IF(L18="","",IF(L18>=0.75,"Proficient",IF(L18>=0.5,"Nearly Proficient",IF(L18>=0.25,"Low Proficient","Not Proficient"))))
L19: =IFERROR(K19/J19,"") | M19: =IF(L19="","",IF(L19>=0.75,"Proficient",IF(L19>=0.5,"Nearly Proficient",IF(L19>=0.25,"Low Proficient","Not Proficient"))))
... L54: =IFERROR(K54/J54,"") | M54: =IF(L54="","",IF(L54>=0.75,"Proficient",IF(L54>=0.5,"Nearly Proficient",IF(L54>=0.25,"Low Proficient","Not Proficient"))))
A57: Dashboard hyperlink formula sample: | B57: =IF(#REF!="","No File",HYPERLINK(#REF!,"View File")) -> #REF!

Sheet View_Only_Sharing_Guide
A1: VIEW-ONLY DASHBOARD SHARING GUIDE Use this guide to let teachers see updates/results without allowing them to edit the workbook.
A5: Method | B5: Recommended Use | C5: Who Can Use | D5: Permission | E5: Steps | F5: Risk Level | G5: Best For | H5: Notes
A6: Excel Online View Only | B6: Fastest deployment | C6: Teachers and principal | D6: Can view only | E6: Upload workbook to SharePoint/OneDrive > Share > Specific people > Can view | F6: Low | G6: Small school setup | H6: Do not share edit link
A7: Power BI Dashboard | B7: Best presentation/viewing experience | C7: Teachers/principal | D7: Viewer only | E7: Connect Power BI to workbook > publish report > share app/dashboard as viewer | F7: Very Low | G7: Formal dashboard viewing | H7: Protects workbook formulas
A8: Power Apps Teacher Portal | B8: Best future upgrade | C8: Teachers/admin/principal | D8: App user only | E8: Build app > filter by User().Email > share as User | F8: Low | G8: Teacher login portal | H8: Requires more setup
A9: Direct Excel Editing | B9: Not recommended for teachers | C9: Admin only | D9: Can edit | E9: Only system owner/admin should edit workbook | F9: High | G9: Admin maintenance | H9: May break formulas if shared broadly
A12: IMPORTANT: Teachers should submit through Microsoft Forms and view through Power BI or Excel Online view-only. Do not give teachers edit access to the main workbook because formulas, table names, and Power Automate mappings can break.

Sheet Access_Control
A1: USER ACCESS AND VIEW-ONLY CONTROL Use this sheet to manage teacher emails, roles, assigned grade/section, and dashboard viewing rights.
A5: UserID | B5: UserName | C5: Email | D5: Role | E5: AssignedGrade | F5: AssignedSection | G5: CanSubmit | H5: CanViewTeacherDashboard | I5: CanViewAllResults | J5: CanEditWorkbook | K5: Status | L5: Notes
A6: 1 | B6: Jenny Queen L. Orillaneda | C6: jenny.teacher@deped.gov.ph | D6: Teacher | E6: Grade 1 | F6: MAGKONO | G6: Yes | H6: Yes | I6: No | J6: No | K6: Active | L6: View own class results only
A7: 2 | B7: Maria Fatima R. Peñanueva | C7: maria.teacher@deped.gov.ph | D7: Teacher | E7: Grade 2 | F7: NARRA | G7: Yes | H7: Yes | I7: No | J7: No | K7: Active | L7: View own class results only
A8: 3 | B8: Jessa Mae R. Flores | C8: jessa.teacher@deped.gov.ph | D8: Teacher | E8: Grade 3 | F8: TOOG | G8: Yes | H8: Yes | I8: No | J8: No | K8: Active | L8: View own class results only
A9: 4 | B9: Alma C. Nayre | C9: alma.teacher@deped.gov.ph | D9: Teacher | E9: Grade 4 | F9: TUGAS | G9: Yes | H9: Yes | I9: No | J9: No | K9: Active | L9: View own class results only
A10: 5 | B10: Lendon B. Abonales | C10: lendon.teacher@deped.gov.ph | D10: Teacher | E10: Grade 5 | F10: LAUAAN | G10: Yes | H10: Yes | I10: No | J10: No | K10: Active | L10: View own class results only
A11: 6 | B11: Mark Zoilo C. Tajonera | C11: mark.teacher@deped.gov.ph | D11: Teacher | E11: Grade 6 | F11: YAKAL | G11: Yes | H11: Yes | I11: No | J11: No | K11: Active | L11: View own class results only
A12: 7 | B12: Jasper S. Campado | C12: jasper_campado@deped.gov.ph | D12: Admin | E12: All | F12: All | G12: Yes | H12: Yes | I12: Yes | J12: Yes | K12: Active | L12: System owner/admin
